Workbook

Sheet 2026년 제부도 통행시간표 (공표자료)
A1: 2026년 1월 통행가능 시간표 | H1: 2026년 2월 통행가능 시간표 | O1: 2026년 3월 통행가능 시간표
A2: 일자 | C2: 1 차 | E2: 2 차 | H2: 일자 | J2: 1 차 | L2: 2 차 | O2: 일자 | Q2: 1 차 | S2: 2 차
C3: ~부터 (열림) | D3: ~까지 (닫힘) | E3: ~부터 (열림) | F3: ~까지 (닫힘) | J3: ~부터 (열림) | K3: ~까지 (닫힘) | L3: ~부터 (열림) | M3: ~까지 (닫힘) | Q3: ~부터 (열림) | R3: ~까지 (닫힘) | S3: ~부터 (열림) | T3: ~까지 (닫힘)
A4: 1 | B4: 목 | C4: 계속통행 | D4: 1356 | E4: 1556 | F4: 계속통행 | H4: 1 | I4: 일 | J4: 계속통행 | K4: 1517 | L4: 1819 | M4: 계속통행 | O4: 1 | P4: 일 | Q4: 계속통행 | R4: 1446 | S4: 1657 | T4: 계속통행
A5: 2 | B5: 금 | C5: 계속통행 | D5: 1431 | E5: 1720 | F5: 계속통행 | H5: 2 | I5: 월 | J5: 계속통행 | K5: 1553 | L5: 1910 | M5: 448 | O5: 2 | P5: 월 | Q5: 계속통행 | R5: 1509 | S5: 1801 | T5: 355
A6: 3 | B6: 토 | C6: 계속통행 | D6: 1513 | E6: 1827 | F6: 계속통행 | H6: 3 | I6: 화 | J6: 628 | K6: 1631 | L6: 1949 | M6: 516 | O6: 3 | P6: 화 | Q6: 533 | R6: 1540 | S6: 1844 | T6: 411
A7: 4 | B7: 일 | C7: 계속통행 | D7: 1558 | E7: 1922 | F7: 530 | H7: 4 | I7: 수 | J7: 719 | K7: 1709 | L7: 2018 | M7: 549 | O7: 4 | P7: 수 | Q7: 632 | R7: 1613 | S7: 1915 | T7: 438
A8: 5 | B8: 월 | C8: 603 | D8: 1644 | E8: 2007 | F8: 601 | H8: 5 | I8: 목 | J8: 758 | K8: 1747 | L8: 2039 | M8: 628 | O8: 5 | P8: 목 | Q8: 714 | R8: 1647 | S8: 1939 | T8: 509
A9: 6 | B9: 화 | C9: 701 | D9: 1729 | E9: 2043 | F9: 644 | H9: 6 | I9: 금 | J9: 827 | K9: 1830 | L9: 2052 | M9: 716 | O9: 6 | P9: 금 | Q9: 748 | R9: 1723 | S9: 1957 | T9: 542
A10: 7 | B10: 수 | C10: 742 | D10: 1816 | E10: 2109 | F10: 계속통행 | H10: 7 | I10: 토 | J10: 843 | K10: 1927 | L10: 2048 | M10: 계속통행 | O10: 7 | P10: 토 | Q10: 814 | R10: 1803 | S10: 2008 | T10: 622
A11: 8 | B11: 목 | C11: 계속통행 | D11: 1909 | E11: 2124 | F11: 계속통행 | H11: 8 | I11: 일 | J11: 계속통행 | K11: 계속통행 | L11: 계속통행 | M11: 계속통행 | O11: 8 | P11: 일 | Q11: 832 | R11: 1859 | S11: 2002 | T11: 716
A12: 9 | B12: 금 | C12: 계속통행 | D12: 2008 | E12: 2110 | F12: 계속통행 | H12: 9 | I12: 월 | J12: 계속통행 | K12: 계속통행 | L12: 계속통행 | M12: 계속통행 | O12: 9 | P12: 월 | Q12: 834 | R12: 계속통행 | S12: 계속통행 | T12: 계속통행
A13: 10 | B13: 토 | C13: 계속통행 | D13: 계속통행 | E13: 계속통행 | F13: 계속통행 | H13: 10 | I13: 화 | J13: 계속통행 | K13: 계속통행 | L13: 계속통행 | M13: 계속통행 | O13: 10 | P13: 화 | Q13: 계속통행 | R13: 계속통행 | S13: 계속통행 | T13: 계속통행
A14: 11 | B14: 일 | C14: 계속통행 | D14: 계속통행 | E14: 계속통행 | F14: 계속통행 | H14: 11 | I14: 수 | J14: 계속통행 | K14: 계속통행 | L14: 계속통행 | M14: 계속통행 | O14: 11 | P14: 수 | Q14: 계속통행 | R14: 계속통행 | S14: 계속통행 | T14: 계속통행
A15: 12 | B15: 월 | C15: 계속통행 | D15: 계속통행 | E15: 계속통행 | F15: 계속통행 | H15: 12 | I15: 목 | J15: 계속통행 | K15: 계속통행 | L15: 계속통행 | M15: 계속통행 | O15: 12 | P15: 목 | Q15: 계속통행 | R15: 계속통행 | S15: 계속통행 | T15: 계속통행
A16: 13 | B16: 화 | C16: 계속통행 | D16: 계속통행 | E16: 계속통행 | F16: 계속통행 | H16: 13 | I16: 금 | J16: 계속통행 | K16: 계속통행 | L16: 계속통행 | M16: 계속통행 | O16: 13 | P16: 금 | Q16: 계속통행 | R16: 계속통행 | S16: 계속통행 | T16: 계속통행
A17: 14 | B17: 수 | C17: 계속통행 | D17: 계속통행 | E17: 계속통행 | F17: 계속통행 | H17: 14 | I17: 토 | J17: 계속통행 | K17: 계속통행 | L17: 계속통행 | M17: 계속통행 | O17: 14 | P17: 토 | Q17: 계속통행 | R17: 계속통행 | S17: 계속통행 | T17: 계속통행
A18: 15 | B18: 목 | C18: 계속통행 | D18: 계속통행 | E18: 계속통행 | F18: 계속통행 | H18: 15 | I18: 일 | J18: 계속통행 | K18: 계속통행 | L18: 계속통행 | M18: 계속통행 | O18: 15 | P18: 일 | Q18: 계속통행 | R18: 계속통행 | S18: 계속통행 | T18: 계속통행
A19: 16 | B19: 금 | C19: 계속통행 | D19: 계속통행 | E19: 계속통행 | F19: 계속통행 | H19: 16 | I19: 월 | J19: 계속통행 | K19: 1535 | L19: 1737 | M19: 계속통행 | O19: 16 | P19: 월 | Q19: 계속통행 | R19: 계속통행 | S19: 계속통행 | T19: 계속통행
A20: 17 | B20: 토 | C20: 계속통행 | D20: 1550 | E20: 1646 | F20: 계속통행 | H20: 17 | I20: 화 | J20: 계속통행 | K20: 1549 | L20: 1829 | M20: 441 | O20: 17 | P20: 화 | Q20: 계속통행 | R20: 1509 | S20: 1701 | T20: 348
A21: 18 | B21: 일 | C21: 계속통행 | D21: 1553 | E21: 1756 | F21: 계속통행 | H21: 18 | I21: 수 | J21: 559 | K21: 1614 | L21: 1909 | M21: 454 | O21: 18 | P21: 수 | Q21: 451 | R21: 1522 | S21: 1756 | T21: 347
A22: 19 | B22: 월 | C22: 계속통행 | D22: 1613 | E22: 1844 | F22: 계속통행 | H22: 19 | I22: 목 | J22: 655 | K22: 1644 | L22: 1943 | M22: 519 | O22: 19 | P22: 목 | Q22: 605 | R22: 1548 | S22: 1838 | T22: 408
A23: 20 | B23: 화 | C23: 계속통행 | D23: 1640 | E23: 1924 | F23: 계속통행 | H23: 20 | I23: 금 | J23: 739 | K23: 1717 | L23: 2012 | M23: 550 | O23: 20 | P23: 금 | Q23: 656 | R23: 1620 | S23: 1913 | T23: 437
A24: 21 | B24: 수 | C24: 계속통행 | D24: 1709 | E24: 1959 | F24: 619 | H24: 21 | I24: 토 | J24: 818 | K24: 1756 | L24: 2035 | M24: 629 | O24: 21 | P24: 토 | Q24: 740 | R24: 1658 | S24: 1941 | T24: 512
A25: 22 | B25: 목 | C25: 712 | D25: 1743 | E25: 2029 | F25: 649 | H25: 22 | I25: 일 | J25: 851 | K25: 1846 | L25: 2051 | M25: 720 | O25: 22 | P25: 일 | Q25: 818 | R25: 1743 | S25: 2004 | T25: 554
A26: 23 | B26: 금 | C26: 753 | D26: 1821 | E26: 2055 | F26: 731 | H26: 23 | I26: 월 | J26: 918 | K26: 계속통행 | L26: 계속통행 | M26: 계속통행 | O26: 23 | P26: 월 | Q26: 852 | R26: 1842 | S26: 2013 | T26: 648
A27: 24 | B27: 토 | C27: 825 | D27: 1910 | E27: 2114 | F27: 계속통행 | H27: 24 | I27: 화 | J27: 계속통행 | K27: 계속통행 | L27: 계속통행 | M27: 계속통행 | O27: 24 | P27: 화 | Q27: 919 | R27: 계속통행 | S27: 계속통행 | T27: 818
A28: 25 | B28: 일 | C28: 계속통행 | D28: 2033 | E28: 2107 | F28: 계속통행 | H28: 25 | I28: 수 | J28: 계속통행 | K28: 계속통행 | L28: 계속통행 | M28: 계속통행 | O28: 25 | P28: 수 | Q28: 923 | R28: 계속통행 | S28: 계속통행 | T28: 계속통행
A29: 26 | B29: 월 | C29: 계속통행 | D29: 계속통행 | E29: 계속통행 | F29: 계속통행 | H29: 26 | I29: 목 | J29: 계속통행 | K29: 계속통행 | L29: 계속통행 | M29: 계속통행 | O29: 26 | P29: 목 | Q29: 계속통행 | R29: 계속통행 | S29: 계속통행 | T29: 계속통행
A30: 27 | B30: 화 | C30: 계속통행 | D30: 계속통행 | E30: 계속통행 | F30: 계속통행 | H30: 27 | I30: 금 | J30: 계속통행 | K30: 계속통행 | L30: 계속통행 | M30: 계속통행 | O30: 27 | P30: 금 | Q30: 계속통행 | R30: 계속통행 | S30: 계속통행 | T30: 계속통행
A31: 28 | B31: 수 | C31: 계속통행 | D31: 계속통행 | E31: 계속통행 | F31: 계속통행 | H31: 28 | I31: 토 | J31: 계속통행 | K31: 계속통행 | L31: 계속통행 | M31: 계속통행 | O31: 28 | P31: 토 | Q31: 계속통행 | R31: 계속통행 | S31: 계속통행 | T31: 계속통행
A32: 29 | B32: 목 | C32: 계속통행 | D32: 계속통행 | E32: 계속통행 | F32: 계속통행 | O32: 29 | P32: 일 | Q32: 계속통행 | R32: 계속통행 | S32: 계속통행 | T32: 계속통행
A33: 30 | B33: 금 | C33: 계속통행 | D33: 계속통행 | E33: 계속통행 | F33: 계속통행 | O33: 30 | P33: 월 | Q33: 계속통행 | R33: 1438 | S33: 1620 | T33: 331
A34: 31 | B34: 토 | C34: 계속통행 | D34: 1445 | E34: 1708 | F34: 계속통행 | O34: 31 | P34: 화 | Q34: 357 | R34: 1456 | S34: 1719 | T34: 317
A35: 2026년 4월 통행가능 시간표 | H35: 2026년 5월 통행가능 시간표 | O35: 2026년 6월 통행가능 시간표
A36: 일자 | C36: 1 차 | E36: 2 차 | H36: 일자 | J36: 1 차 | L36: 2 차 | O36: 일자 | Q36: 1 차 | S36: 2 차
C37: ~부터 (열림) | D37: ~까지 (닫힘) | E37: ~부터 (열림) | F37: ~까지 (닫힘) | J37: ~부터 (열림) | K37: ~까지 (닫힘) | L37: ~부터 (열림) | M37: ~까지 (닫힘) | Q37: ~부터 (열림) | R37: ~까지 (닫힘) | S37: ~부터 (열림) | T37: ~까지 (닫힘)
A38: 1 | B38: 수 | C38: 528 | D38: 1525 | E38: 1757 | F38: 337 | H38: 1 | I38: 금 | J38: 551 | K38: 1552 | L38: 1722 | M38: 336 | O38: 1 | P38: 월 | Q38: 636 | R38: 계속통행 | S38: 계속통행 | T38: 419
A39: 2 | B39: 목 | C39: 618 | D39: 1557 | E39: 1826 | F39: 404 | H39: 2 | I39: 토 | J39: 628 | K39: 1629 | L39: 1747 | M39: 407 | O39: 2 | P39: 화 | Q39: 709 | R39: 계속통행 | S39: 계속통행 | T39: 452
A40: 3 | B40: 금 | C40: 656 | D40: 1631 | E40: 1849 | F40: 434 | H40: 3 | I40: 일 | J40: 700 | K40: 1713 | L40: 1803 | M40: 439 | O40: 3 | P40: 수 | Q40: 740 | R40: 계속통행 | S40: 계속통행 | T40: 527
...

Sheet 2025년 제부도 통행시간표 (현장자료)
A1: 2025년 7월 통행가능 시간표 | H1: 2025년 8월 통행가능 시간표 | O1: 2025년 9월 통행가능 시간표
A2: 일자 | C2: 1 차 | E2: 2 차 | H2: 일자 | J2: 1 차 | L2: 2 차 | O2: 일자 | Q2: 1 차 | S2: 2 차
C3: ~부터 (열림) | D3: ~까지 (닫힘) | E3: ~부터 (열림) | F3: ~까지 (닫힘) | J3: ~부터 (열림) | K3: ~까지 (닫힘) | L3: ~부터 (열림) | M3: ~까지 (닫힘) | Q3: ~부터 (열림) | R3: ~까지 (닫힘) | S3: ~부터 (열림) | T3: ~까지 (닫힘)
A4: 1 | B4: 화 | C4: 0.40138889 | D4: 계속통행 | E4: 계속통행 | F4: 0.37638889 | H4: 1 | I4: 금 | J4: 계속통행 | K4: 계속통행 | L4: 계속통행 | M4: 계속통행 | O4: 1 | P4: 월 | Q4: 계속통행 | R4: 계속통행 | S4: 계속통행 | T4: 계속통행
A5: 2 | B5: 수 | C5: 0.40416667 | D5: 계속통행 | E5: 계속통행 | F5: 계속통행 | H5: 2 | I5: 토 | J5: 계속통행 | K5: 계속통행 | L5: 계속통행 | M5: 계속통행 | O5: 2 | P5: 화 | Q5: 계속통행 | R5: 계속통행 | S5: 계속통행 | T5: 계속통행
A6: 3 | B6: 목 | C6: 계속통행 | D6: 계속통행 | E6: 계속통행 | F6: 계속통행 | H6: 3 | I6: 일 | J6: 계속통행 | K6: 계속통행 | L6: 계속통행 | M6: 계속통행 | O6: 3 | P6: 수 | Q6: 계속통행 | R6: 계속통행 | S6: 계속통행 | T6: 계속통행
A7: 4 | B7: 금 | C7: 계속통행 | D7: 계속통행 | E7: 계속통행 | F7: 계속통행 | H7: 4 | I7: 월 | J7: 계속통행 | K7: 계속통행 | L7: 계속통행 | M7: 계속통행 | O7: 4 | P7: 목 | Q7: 계속통행 | R7: 계속통행 | S7: 계속통행 | T7: 계속통행
A8: 5 | B8: 토 | C8: 계속통행 | D8: 계속통행 | E8: 계속통행 | F8: 계속통행 | H8: 5 | I8: 화 | J8: 계속통행 | K8: 계속통행 | L8: 계속통행 | M8: 계속통행 | O8: 5 | P8: 금 | Q8: 계속통행 | R8: 계속통행 | S8: 계속통행 | T8: 0.1
A9: 6 | B9: 일 | C9: 계속통행 | D9: 계속통행 | E9: 계속통행 | F9: 계속통행 | H9: 6 | I9: 수 | J9: 계속통행 | K9: 계속통행 | L9: 계속통행 | M9: 0.11527778 | O9: 6 | P9: 토 | Q9: 0.21944444 | R9: 0.62847222 | S9: 0.70625 | T9: 0.11319444
A10: 7 | B10: 월 | C10: 계속통행 | D10: 계속통행 | E10: 계속통행 | F10: 계속통행 | H10: 7 | I10: 목 | J10: 0.175 | K10: 계속통행 | L10: 계속통행 | M10: 0.11111111 | O10: 7 | P10: 일 | Q10: 0.25 | R10: 0.63611111 | S10: 0.73263889 | T10: 0.12916667
A11: 8 | B11: 화 | C11: 계속통행 | D11: 계속통행 | E11: 계속통행 | F11: 0.11458333 | H11: 8 | I11: 금 | J11: 0.23194444 | K11: 계속통행 | L11: 계속통행 | M11: 0.12986111 | O11: 8 | P11: 월 | Q11: 0.28125 | R11: 0.64791667 | S11: 0.77708333 | T11: 0.15555556
A12: 9 | B12: 수 | C12: 0.19791667 | D12: 계속통행 | E12: 계속통행 | F12: 0.12708333 | H12: 9 | I12: 토 | J12: 0.26666667 | K12: 0.67222222 | L12: 0.725 | M12: 0.15 | O12: 9 | P12: 화 | Q12: 0.30347222 | R12: 0.66875 | S12: 0.81180556 | T12: 0.17569444
A13: 10 | B13: 목 | C13: 0.23819444 | D13: 계속통행 | E13: 계속통행 | F13: 0.13888889 | H13: 10 | I13: 일 | J13: 0.29722222 | K13: 0.68125 | L13: 0.76944444 | M13: 0.17222222 | O13: 10 | P13: 수 | Q13: 0.32916667 | R13: 0.69375 | S13: 0.84027778 | T13: 0.20833333
A14: 11 | B14: 금 | C14: 0.27916667 | D14: 0.70694444 | E14: 0.73055556 | F14: 0.16736111 | H14: 11 | I14: 월 | J14: 0.325 | K14: 0.69791667 | L14: 0.80833333 | M14: 0.19583333 | O14: 11 | P14: 목 | Q14: 0.34652778 | R14: 0.71875 | S14: 0.87013889 | T14: 0.23541667
A15: 12 | B15: 토 | C15: 0.31041667 | D15: 0.72291667 | E15: 0.74722222 | F15: 0.19236111 | H15: 12 | I15: 화 | J15: 0.34791667 | K15: 0.71875 | L15: 0.84305556 | M15: 0.21875 | O15: 12 | P15: 금 | Q15: 0.36111111 | R15: 0.74861111 | S15: 0.89236111 | T15: 0.27569444
A16: 13 | B16: 일 | C16: 0.33680556 | D16: 0.73680556 | E16: 0.78958333 | F16: 0.21180556 | H16: 13 | I16: 수 | J16: 0.37430556 | K16: 0.73958333 | L16: 0.86666667 | M16: 0.25 | O16: 13 | P16: 토 | Q16: 0.36944444 | R16: 0.8 | S16: 0.90625 | T16: 계속통행
A17: 14 | B17: 월 | C17: 0.35972222 | D17: 0.75833333 | E17: 0.81736111 | F17: 0.23611111 | H17: 14 | I17: 목 | J17: 0.39027778 | K17: 0.78333333 | L17: 0.89236111 | M17: 0.29444444 | O17: 14 | P17: 일 | Q17: 계속통행 | R17: 0.85555556 | S17: 0.92083333 | T17: 계속통행
A18: 15 | B18: 화 | C18: 0.38263889 | D18: 0.78263889 | E18: 0.85416667 | F18: 0.26944444 | H18: 15 | I18: 금 | J18: 0.39027778 | K18: 0.81944444 | L18: 0.91597222 | M18: 계속통행 | O18: 15 | P18: 월 | Q18: 계속통행 | R18: 계속통행 | S18: 계속통행 | T18: 계속통행
A19: 16 | B19: 수 | C19: 0.40763889 | D19: 0.79861111 | E19: 0.9 | F19: 0.29722222 | H19: 16 | I19: 토 | J19: 계속통행 | K19: 0.88472222 | L19: 0.92638889 | M19: 계속통행 | O19: 16 | P19: 화 | Q19: 계속통행 | R19: 계속통행 | S19: 계속통행 | T19: 계속통행
A20: 17 | B20: 목 | C20: 0.42152778 | D20: 0.8625 | E20: 0.90486111 | F20: 0.36180556 | H20: 17 | I20: 일 | J20: 계속통행 | K20: 계속통행 | L20: 계속통행 | M20: 계속통행 | O20: 17 | P20: 수 | Q20: 계속통행 | R20: 계속통행 | S20: 계속통행 | T20: 계속통행
A21: 18 | B21: 금 | C21: 0.42222222 | D21: 계속통행 | E21: 계속통행 | F21: 계속통행 | H21: 18 | I21: 월 | J21: 계속통행 | K21: 계속통행 | L21: 계속통행 | M21: 계속통행 | O21: 18 | P21: 목 | Q21: 계속통행 | R21: 계속통행 | S21: 계속통행 | T21: 0.078472222
A22: 19 | B22: 토 | C22: 계속통행 | D22: 계속통행 | E22: 계속통행 | F22: 계속통행 | H22: 19 | I22: 화 | J22: 계속통행 | K22: 계속통행 | L22: 계속통행 | M22: 계속통행 | O22: 19 | P22: 금 | Q22: 0.175 | R22: 계속통행 | S22: 계속통행 | T22: 0.084027778
A23: 20 | B23: 일 | C23: 계속통행 | D23: 계속통행 | E23: 계속통행 | F23: 계속통행 | H23: 20 | I23: 수 | J23: 계속통행 | K23: 계속통행 | L23: 계속통행 | M23: 0.08125 | O23: 20 | P23: 토 | Q23: 0.21944444 | R23: 0.63888889 | S23: 0.69097222 | T23: 0.12152778
A24: 21 | B24: 월 | C24: 계속통행 | D24: 계속통행 | E24: 계속통행 | F24: 0.054166667 | H24: 21 | I24: 목 | J24: 0.1875 | K24: 계속통행 | L24: 계속통행 | M24: 0.10416667 | O24: 21 | P24: 일 | Q24: 0.24305556 | R24: 0.63402778 | S24: 0.74305556 | T24: 0.13263889
A25: 22 | B25: 화 | C25: 0.12847222 | D25: 계속통행 | E25: 계속통행 | F25: 0.079861111 | H25: 22 | I25: 금 | J25: 0.23333333 | K25: 0.64513889 | L25: 0.69791667 | M25: 0.12916667 | O25: 22 | P25: 월 | Q25: 0.27430556 | R25: 0.64722222 | S25: 0.78333333 | T25: 0.16111111
A26: 23 | B26: 수 | C26: 0.19583333 | D26: 계속통행 | E26: 계속통행 | F26: 0.10625 | H26: 23 | I26: 토 | J26: 0.27083333 | K26: 0.65069444 | L26: 0.74444444 | M26: 0.15208333 | O26: 23 | P26: 화 | Q26: 0.29236111 | R26: 0.67361111 | S26: 0.80416667 | T26: 0.18125
A27: 24 | B27: 목 | C27: 0.24791667 | D27: 계속통행 | E27: 계속통행 | F27: 0.13472222 | H27: 24 | I27: 일 | J27: 0.29652778 | K27: 0.675 | L27: 0.78055556 | M27: 0.17291667 | O27: 24 | P27: 수 | Q27: 0.3125 | R27: 0.68333333 | S27: 0.82430556 | T27: 0.20763889
A28: 25 | B28: 금 | C28: 0.28819444 | D28: 0.67638889 | E28: 0.75555556 | F28: 0.15972222 | H28: 25 | I28: 월 | J28: 0.32013889 | K28: 0.69027778 | L28: 0.8125 | M28: 0.19444444 | O28: 25 | P28: 목 | Q28: 0.31319444 | R28: 0.70972222 | S28: 0.83472222 | T28: 0.24097222
A29: 26 | B29: 토 | C29: 0.32361111 | D29: 0.70138889 | E29: 0.78611111 | F29: 0.1875 | H29: 26 | I29: 화 | J29: 0.33541667 | K29: 0.71805556 | L29: 0.82777778 | M29: 0.22291667 | O29: 26 | P29: 금 | Q29: 0.31388889 | R29: 0.73611111 | S29: 0.84583333 | T29: 계속통행
A30: 27 | B30: 일 | C30: 0.34722222 | D30: 0.71944444 | E30: 0.82152778 | F30: 0.21527778 | H30: 27 | I30: 수 | J30: 0.34097222 | K30: 0.73611111 | L30: 0.85138889 | M30: 0.25 | O30: 27 | P30: 토 | Q30: 계속통행 | R30: 0.76319444 | S30: 0.85486111 | T30: 계속통행
A31: 28 | B31: 월 | C31: 0.36666667 | D31: 0.74791667 | E31: 0.84583333 | F31: 0.24305556 | H31: 28 | I31: 목 | J31: 0.35486111 | K31: 0.76111111 | L31: 0.86597222 | M31: 0.27916667 | O31: 28 | P31: 일 | Q31: 계속통행 | R31: 계속통행 | S31: 계속통행 | T31: 계속통행
A32: 29 | B32: 화 | C32: 0.37777778 | D32: 0.77152778 | E32: 0.87013889 | F32: 0.26736111 | H32: 29 | I32: 금 | J32: 0.35138889 | K32: 0.80277778 | L32: 0.85833333 | M32: 계속통행 | O32: 29 | P32: 월 | Q32: 계속통행 | R32: 계속통행 | S32: 계속통행 | T32: 계속통행
A33: 30 | B33: 수 | C33: 0.39375 | D33: 0.8 | E33: 0.88472222 | F33: 0.30694444 | H33: 30 | I33: 토 | J33: 계속통행 | K33: 계속통행 | L33: 계속통행 | M33: 계속통행 | O33: 30 | P33: 화 | Q33: 계속통행 | R33: 계속통행 | S33: 계속통행 | T33: 계속통행
A34: 31 | B34: 목 | C34: 0.39444444 | D34: 계속통행 | E34: 계속통행 | F34: 계속통행 | H34: 31 | I34: 일 | J34: 계속통행 | K34: 계속통행 | L34: 계속통행 | M34: 계속통행
A35: 2025년 10월 통행가능 시간표 | H35: 2025년 11월 통행가능 시간표 | O35: 2025년 12월 통행가능 시간표
A36: 일자 | C36: 1 차 | E36: 2 차 | H36: 일자 | J36: 1 차 | L36: 2 차 | O36: 일자 | Q36: 1 차 | S36: 2 차
C37: ~부터 (열림) | D37: ~까지 (닫힘) | E37: ~부터 (열림) | F37: ~까지 (닫힘) | J37: ~부터 (열림) | K37: ~까지 (닫힘) | L37: ~부터 (열림) | M37: ~까지 (닫힘) | Q37: ~부터 (열림) | R37: ~까지 (닫힘) | S37: ~부터 (열림) | T37: ~까지 (닫힘)
A38: 1 | B38: 수 | C38: 계속통행 | D38: 계속통행 | E38: 계속통행 | F38: 계속통행 | H38: 1 | I38: 토 | J38: 계속통행 | K38: 계속통행 | L38: 계속통행 | M38: 계속통행 | O38: 1 | P38: 월
A39: 2 | B39: 목 | C39: 계속통행 | D39: 계속통행 | E39: 계속통행 | F39: 계속통행 | H39: 2 | I39: 일 | J39: 계속통행 | K39: 계속통행 | L39: 계속통행 | M39: 계속통행 | O39: 2 | P39: 화
A40: 3 | B40: 금 | C40: 계속통행 | D40: 계속통행 | E40: 계속통행 | F40: 계속통행 | H40: 3 | I40: 월 | J40: 계속통행 | K40: 0.57777778 | L40: 0.66458333 | M40: 0.076388889 | O40: 3 | P40: 수
...

Sheet 2025년 제부도 통행시간표 (편차)
A1: 2025년 7월 통행가능 시간표 | H1: 2025년 8월 통행가능 시간표 | O1: 2025년 9월 통행가능 시간표
A2: 일자 | C2: 1 차 | E2: 2 차 | H2: 일자 | J2: 1 차 | L2: 2 차 | O2: 일자 | Q2: 1 차 | S2: 2 차
C3: ~부터 (열림) | D3: ~까지 (닫힘) | E3: ~부터 (열림) | F3: ~까지 (닫힘) | J3: ~부터 (열림) | K3: ~까지 (닫힘) | L3: ~부터 (열림) | M3: ~까지 (닫힘) | Q3: ~부터 (열림) | R3: ~까지 (닫힘) | S3: ~부터 (열림) | T3: ~까지 (닫힘)
A4: 1 | B4: 화 | C4: ='2025년 제부도 통행시간표 (현장자료)'!C4-'2026년 제부도 통행시간표 (공표자료)'!C72 -> -701.59861 | F4: ='2025년 제부도 통행시간표 (현장자료)'!F4-'2026년 제부도 통행시간표 (공표자료)'!F72 -> -428.62361 | H4: 1 | I4: 금 | O4: 1 | P4: 월
A5: 2 | B5: 수 | C5: ='2025년 제부도 통행시간표 (현장자료)'!C5-'2026년 제부도 통행시간표 (공표자료)'!C73 -> -738.59583 | H5: 2 | I5: 토 | O5: 2 | P5: 화
A6: 3 | B6: 목 | H6: 3 | I6: 일 | O6: 3 | P6: 수
A7: 4 | B7: 금 | H7: 4 | I7: 월 | O7: 4 | P7: 목
A8: 5 | B8: 토 | H8: 5 | I8: 화 | O8: 5 | P8: 금 | T8: ='2025년 제부도 통행시간표 (현장자료)'!T8-'2026년 제부도 통행시간표 (공표자료)'!T76 -> #VALUE!
A9: 6 | B9: 일 | H9: 6 | I9: 수 | M9: ='2025년 제부도 통행시간표 (현장자료)'!M9-'2026년 제부도 통행시간표 (공표자료)'!M77 -> #VALUE! | O9: 6 | P9: 토 | Q9: ='2025년 제부도 통행시간표 (현장자료)'!Q9-'2026년 제부도 통행시간표 (공표자료)'!Q77 -> #VALUE! | T9: ='2025년 제부도 통행시간표 (현장자료)'!T9-'2026년 제부도 통행시간표 (공표자료)'!T77 -> #VALUE!
A10: 7 | B10: 월 | H10: 7 | I10: 목 | J10: ='2025년 제부도 통행시간표 (현장자료)'!J10-'2026년 제부도 통행시간표 (공표자료)'!J78 -> #VALUE! | M10: ='2025년 제부도 통행시간표 (현장자료)'!M10-'2026년 제부도 통행시간표 (공표자료)'!M78 -> #VALUE! | O10: 7 | P10: 일 | Q10: ='2025년 제부도 통행시간표 (현장자료)'!Q10-'2026년 제부도 통행시간표 (공표자료)'!Q78 -> #VALUE! | R10: ='2025년 제부도 통행시간표 (현장자료)'!R10-'2026년 제부도 통행시간표 (공표자료)'!R78 -> #VALUE! | S10: ='2025년 제부도 통행시간표 (현장자료)'!S10-'2026년 제부도 통행시간표 (공표자료)'!S78 -> #VALUE! | T10: ='2025년 제부도 통행시간표 (현장자료)'!T10-'2026년 제부도 통행시간표 (공표자료)'!T78 -> -137.87083
A11: 8 | B11: 화 | F11: ='2025년 제부도 통행시간표 (현장자료)'!F11-'2026년 제부도 통행시간표 (공표자료)'!F79 -> #VALUE! | H11: 8 | I11: 금 | J11: ='2025년 제부도 통행시간표 (현장자료)'!J11-'2026년 제부도 통행시간표 (공표자료)'!J79 -> #VALUE! | M11: ='2025년 제부도 통행시간표 (현장자료)'!M11-'2026년 제부도 통행시간표 (공표자료)'!M79 -> #VALUE! | O11: 8 | P11: 월 | Q11: ='2025년 제부도 통행시간표 (현장자료)'!Q11-'2026년 제부도 통행시간표 (공표자료)'!Q79 -> -255.71875 | R11: ='2025년 제부도 통행시간표 (현장자료)'!R11-'2026년 제부도 통행시간표 (공표자료)'!R79 -> #VALUE! | S11: ='2025년 제부도 통행시간표 (현장자료)'!S11-'2026년 제부도 통행시간표 (공표자료)'!S79 -> #VALUE! | T11: ='2025년 제부도 통행시간표 (현장자료)'!T11-'2026년 제부도 통행시간표 (공표자료)'!T79 -> -147.84444
A12: 9 | B12: 수 | C12: ='2025년 제부도 통행시간표 (현장자료)'!C12-'2026년 제부도 통행시간표 (공표자료)'!C80 -> #VALUE! | F12: ='2025년 제부도 통행시간표 (현장자료)'!F12-'2026년 제부도 통행시간표 (공표자료)'!F80 -> #VALUE! | H12: 9 | I12: 토 | J12: ='2025년 제부도 통행시간표 (현장자료)'!J12-'2026년 제부도 통행시간표 (공표자료)'!J80 -> #VALUE! | K12: ='2025년 제부도 통행시간표 (현장자료)'!K12-'2026년 제부도 통행시간표 (공표자료)'!K80 -> #VALUE! | L12: ='2025년 제부도 통행시간표 (현장자료)'!L12-'2026년 제부도 통행시간표 (공표자료)'!L80 -> #VALUE! | M12: ='2025년 제부도 통행시간표 (현장자료)'!M12-'2026년 제부도 통행시간표 (공표자료)'!M80 -> -119.85 | O12: 9 | P12: 화 | Q12: ='2025년 제부도 통행시간표 (현장자료)'!Q12-'2026년 제부도 통행시간표 (공표자료)'!Q80 -> -446.69653 | R12: ='2025년 제부도 통행시간표 (현장자료)'!R12-'2026년 제부도 통행시간표 (공표자료)'!R80 -> -1455.3312 | S12: ='2025년 제부도 통행시간표 (현장자료)'!S12-'2026년 제부도 통행시간표 (공표자료)'!S80 -> -1605.1882 | T12: ='2025년 제부도 통행시간표 (현장자료)'!T12-'2026년 제부도 통행시간표 (공표자료)'!T80 -> -217.82431
A13: 10 | B13: 목 | C13: ='2025년 제부도 통행시간표 (현장자료)'!C13-'2026년 제부도 통행시간표 (공표자료)'!C81 -> #VALUE! | F13: ='2025년 제부도 통행시간표 (현장자료)'!F13-'2026년 제부도 통행시간표 (공표자료)'!F81 -> -48.861111 | H13: 10 | I13: 일 | J13: ='2025년 제부도 통행시간표 (현장자료)'!J13-'2026년 제부도 통행시간표 (공표자료)'!J81 -> -310.70278 | K13: ='2025년 제부도 통행시간표 (현장자료)'!K13-'2026년 제부도 통행시간표 (공표자료)'!K81 -> #VALUE! | L13: ='2025년 제부도 통행시간표 (현장자료)'!L13-'2026년 제부도 통행시간표 (공표자료)'!L81 -> #VALUE! | M13: ='2025년 제부도 통행시간표 (현장자료)'!M13-'2026년 제부도 통행시간표 (공표자료)'!M81 -> -148.82778 | O13: 10 | P13: 수 | Q13: ='2025년 제부도 통행시간표 (현장자료)'!Q13-'2026년 제부도 통행시간표 (공표자료)'!Q81 -> -547.67083 | R13: ='2025년 제부도 통행시간표 (현장자료)'!R13-'2026년 제부도 통행시간표 (공표자료)'!R81 -> -1456.3063 | S13: ='2025년 제부도 통행시간표 (현장자료)'!S13-'2026년 제부도 통행시간표 (공표자료)'!S81 -> -1734.1597 | T13: ='2025년 제부도 통행시간표 (현장자료)'!T13-'2026년 제부도 통행시간표 (공표자료)'!T81 -> -252.79167
A14: 11 | B14: 금 | C14: ='2025년 제부도 통행시간표 (현장자료)'!C14-'2026년 제부도 통행시간표 (공표자료)'!C82 -> -118.72083 | F14: ='2025년 제부도 통행시간표 (현장자료)'!F14-'2026년 제부도 통행시간표 (공표자료)'!F82 -> -106.83264 | H14: 11 | I14: 월 | J14: ='2025년 제부도 통행시간표 (현장자료)'!J14-'2026년 제부도 통행시간표 (공표자료)'!J82 -> -499.675 | K14: ='2025년 제부도 통행시간표 (현장자료)'!K14-'2026년 제부도 통행시간표 (공표자료)'!K82 -> #VALUE! | L14: ='2025년 제부도 통행시간표 (현장자료)'!L14-'2026년 제부도 통행시간표 (공표자료)'!L82 -> #VALUE! | M14: ='2025년 제부도 통행시간표 (현장자료)'!M14-'2026년 제부도 통행시간표 (공표자료)'!M82 -> -226.80417 | O14: 11 | P14: 목 | Q14: ='2025년 제부도 통행시간표 (현장자료)'!Q14-'2026년 제부도 통행시간표 (공표자료)'!Q82 -> -632.65347 | R14: ='2025년 제부도 통행시간표 (현장자료)'!R14-'2026년 제부도 통행시간표 (공표자료)'!R82 -> -1520.2812 | S14: ='2025년 제부도 통행시간표 (현장자료)'!S14-'2026년 제부도 통행시간표 (공표자료)'!S82 -> -1830.1299 | T14: ='2025년 제부도 통행시간표 (현장자료)'!T14-'2026년 제부도 통행시간표 (공표자료)'!T82 -> -328.76458
A15: 12 | B15: 토 | C15: ='2025년 제부도 통행시간표 (현장자료)'!C15-'2026년 제부도 통행시간표 (공표자료)'!C83 -> -330.68958 | D15: ='2025년 제부도 통행시간표 (현장자료)'!D15-'2026년 제부도 통행시간표 (공표자료)'!D83 -> #VALUE! | E15: ='2025년 제부도 통행시간표 (현장자료)'!E15-'2026년 제부도 통행시간표 (공표자료)'!E83 -> #VALUE! | F15: ='2025년 제부도 통행시간표 (현장자료)'!F15-'2026년 제부도 통행시간표 (공표자료)'!F83 -> -147.80764 | H15: 12 | I15: 화 | J15: ='2025년 제부도 통행시간표 (현장자료)'!J15-'2026년 제부도 통행시간표 (공표자료)'!J83 -> -610.65208 | K15: ='2025년 제부도 통행시간표 (현장자료)'!K15-'2026년 제부도 통행시간표 (공표자료)'!K83 -> -1526.2812 | L15: ='2025년 제부도 통행시간표 (현장자료)'!L15-'2026년 제부도 통행시간표 (공표자료)'!L83 -> -1728.1569 | M15: ='2025년 제부도 통행시간표 (현장자료)'!M15-'2026년 제부도 통행시간표 (공표자료)'!M83 -> -305.78125 | O15: 12 | P15: 금 | Q15: ='2025년 제부도 통행시간표 (현장자료)'!Q15-'2026년 제부도 통행시간표 (공표자료)'!Q83 -> -706.63889 | R15: ='2025년 제부도 통행시간표 (현장자료)'!R15-'2026년 제부도 통행시간표 (공표자료)'!R83 -> -1550.2514 | S15: ='2025년 제부도 통행시간표 (현장자료)'!S15-'2026년 제부도 통행시간표 (공표자료)'!S83 -> -1914.1076 | T15: ='2025년 제부도 통행시간표 (현장자료)'!T15-'2026년 제부도 통행시간표 (공표자료)'!T83 -> -405.72431
A16: 13 | B16: 일 | C16: ='2025년 제부도 통행시간표 (현장자료)'!C16-'2026년 제부도 통행시간표 (공표자료)'!C84 -> -502.66319 | D16: ='2025년 제부도 통행시간표 (현장자료)'!D16-'2026년 제부도 통행시간표 (공표자료)'!D84 -> #VALUE! | E16: ='2025년 제부도 통행시간표 (현장자료)'!E16-'2026년 제부도 통행시간표 (공표자료)'!E84 -> #VALUE! | F16: ='2025년 제부도 통행시간표 (현장자료)'!F16-'2026년 제부도 통행시간표 (공표자료)'!F84 -> -231.78819 | H16: 13 | I16: 수 | J16: ='2025년 제부도 통행시간표 (현장자료)'!J16-'2026년 제부도 통행시간표 (공표자료)'!J84 -> -702.62569 | K16: ='2025년 제부도 통행시간표 (현장자료)'!K16-'2026년 제부도 통행시간표 (공표자료)'!K84 -> -1551.2604 | L16: ='2025년 제부도 통행시간표 (현장자료)'!L16-'2026년 제부도 통행시간표 (공표자료)'!L84 -> -1834.1333 | M16: ='2025년 제부도 통행시간표 (현장자료)'!M16-'2026년 제부도 통행시간표 (공표자료)'!M84 -> -345.75 | O16: 13 | P16: 토 | Q16: ='2025년 제부도 통행시간표 (현장자료)'!Q16-'2026년 제부도 통행시간표 (공표자료)'!Q84 -> -734.63056 | R16: ='2025년 제부도 통행시간표 (현장자료)'!R16-'2026년 제부도 통행시간표 (공표자료)'!R84 -> -1623.2 | S16: ='2025년 제부도 통행시간표 (현장자료)'!S16-'2026년 제부도 통행시간표 (공표자료)'!S84 -> -1951.0938
A17: 14 | B17: 월 | C17: ='2025년 제부도 통행시간표 (현장자료)'!C17-'2026년 제부도 통행시간표 (공표자료)'!C85 -> -615.64028 | D17: ='2025년 제부도 통행시간표 (현장자료)'!D17-'2026년 제부도 통행시간표 (공표자료)'!D85 -> -1552.2417 | E17: ='2025년 제부도 통행시간표 (현장자료)'!E17-'2026년 제부도 통행시간표 (공표자료)'!E85 -> -1712.1826 | F17: ='2025년 제부도 통행시간표 (현장자료)'!F17-'2026년 제부도 통행시간표 (공표자료)'!F85 -> -316.76389 | H17: 14 | I17: 목 | J17: ='2025년 제부도 통행시간표 (현장자료)'!J17-'2026년 제부도 통행시간표 (공표자료)'!J85 -> -744.60972 | K17: ='2025년 제부도 통행시간표 (현장자료)'!K17-'2026년 제부도 통행시간표 (공표자료)'!K85 -> -1622.2167 | L17: ='2025년 제부도 통행시간표 (현장자료)'!L17-'2026년 제부도 통행시간표 (공표자료)'!L85 -> -1925.1076 | M17: ='2025년 제부도 통행시간표 (현장자료)'!M17-'2026년 제부도 통행시간표 (공표자료)'!M85 -> -424.70556 | O17: 14 | P17: 일
A18: 15 | B18: 화 | C18: ='2025년 제부도 통행시간표 (현장자료)'!C18-'2026년 제부도 통행시간표 (공표자료)'!C86 -> -715.61736 | D18: ='2025년 제부도 통행시간표 (현장자료)'!D18-'2026년 제부도 통행시간표 (공표자료)'!D86 -> -1621.2174 | E18: ='2025년 제부도 통행시간표 (현장자료)'!E18-'2026년 제부도 통행시간표 (공표자료)'!E86 -> -1824.1458 | F18: ='2025년 제부도 통행시간표 (현장자료)'!F18-'2026년 제부도 통행시간표 (공표자료)'!F86 -> -401.73056 | H18: 15 | I18: 금 | J18: ='2025년 제부도 통행시간표 (현장자료)'!J18-'2026년 제부도 통행시간표 (공표자료)'!J86 -> -817.60972 | K18: ='2025년 제부도 통행시간표 (현장자료)'!K18-'2026년 제부도 통행시간표 (공표자료)'!K86 -> -1657.1806 | L18: ='2025년 제부도 통행시간표 (현장자료)'!L18-'2026년 제부도 통행시간표 (공표자료)'!L86 -> -2008.084 | O18: 15 | P18: 월
A19: 16 | B19: 수 | C19: ='2025년 제부도 통행시간표 (현장자료)'!C19-'2026년 제부도 통행시간표 (공표자료)'!C87 -> -804.59236 | D19: ='2025년 제부도 통행시간표 (현장자료)'!D19-'2026년 제부도 통행시간표 (공표자료)'!D87 -> -1657.2014 | E19: ='2025년 제부도 통행시간표 (현장자료)'!E19-'2026년 제부도 통행시간표 (공표자료)'!E87 -> -1921.1 | F19: ='2025년 제부도 통행시간표 (현장자료)'!F19-'2026년 제부도 통행시간표 (공표자료)'!F87 -> -445.70278 | H19: 16 | I19: 토 | K19: ='2025년 제부도 통행시간표 (현장자료)'!K19-'2026년 제부도 통행시간표 (공표자료)'!K87 -> -1734.1153 | L19: ='2025년 제부도 통행시간표 (현장자료)'!L19-'2026년 제부도 통행시간표 (공표자료)'!L87 -> -2043.0736 | O19: 16 | P19: 화
A20: 17 | B20: 목 | C20: ='2025년 제부도 통행시간표 (현장자료)'!C20-'2026년 제부도 통행시간표 (공표자료)'!C88 -> -845.57847 | D20: ='2025년 제부도 통행시간표 (현장자료)'!D20-'2026년 제부도 통행시간표 (공표자료)'!D88 -> -1736.1375 | E20: ='2025년 제부도 통행시간표 (현장자료)'!E20-'2026년 제부도 통행시간표 (공표자료)'!E88 -> -2009.0951 | F20: ='2025년 제부도 통행시간표 (현장자료)'!F20-'2026년 제부도 통행시간표 (공표자료)'!F88 -> -528.63819 | H20: 17 | I20: 일 | O20: 17 | P20: 수
A21: 18 | B21: 금 | C21: ='2025년 제부도 통행시간표 (현장자료)'!C21-'2026년 제부도 통행시간표 (공표자료)'!C89 -> -918.57778 | H21: 18 | I21: 월 | O21: 18 | P21: 목 | T21: ='2025년 제부도 통행시간표 (현장자료)'!T21-'2026년 제부도 통행시간표 (공표자료)'!T89 -> #VALUE!
A22: 19 | B22: 토 | H22: 19 | I22: 화 | O22: 19 | P22: 금 | Q22: ='2025년 제부도 통행시간표 (현장자료)'!Q22-'2026년 제부도 통행시간표 (공표자료)'!Q90 -> #VALUE! | T22: ='2025년 제부도 통행시간표 (현장자료)'!T22-'2026년 제부도 통행시간표 (공표자료)'!T90 -> #VALUE!
A23: 20 | B23: 일 | H23: 20 | I23: 수 | M23: ='2025년 제부도 통행시간표 (현장자료)'!M23-'2026년 제부도 통행시간표 (공표자료)'!M91 -> #VALUE! | O23: 20 | P23: 토 | Q23: ='2025년 제부도 통행시간표 (현장자료)'!Q23-'2026년 제부도 통행시간표 (공표자료)'!Q91 -> #VALUE! | R23: ='2025년 제부도 통행시간표 (현장자료)'!R23-'2026년 제부도 통행시간표 (공표자료)'!R91 -> #VALUE! | S23: ='2025년 제부도 통행시간표 (현장자료)'!S23-'2026년 제부도 통행시간표 (공표자료)'!S91 -> #VALUE! | T23: ='2025년 제부도 통행시간표 (현장자료)'!T23-'2026년 제부도 통행시간표 (공표자료)'!T91 -> #VALUE!
A24: 21 | B24: 월 | F24: ='2025년 제부도 통행시간표 (현장자료)'!F24-'2026년 제부도 통행시간표 (공표자료)'!F92 -> #VALUE! | H24: 21 | I24: 목 | J24: ='2025년 제부도 통행시간표 (현장자료)'!J24-'2026년 제부도 통행시간표 (공표자료)'!J92 -> #VALUE! | M24: ='2025년 제부도 통행시간표 (현장자료)'!M24-'2026년 제부도 통행시간표 (공표자료)'!M92 -> #VALUE! | O24: 21 | P24: 일 | Q24: ='2025년 제부도 통행시간표 (현장자료)'!Q24-'2026년 제부도 통행시간표 (공표자료)'!Q92 -> #VALUE! | R24: ='2025년 제부도 통행시간표 (현장자료)'!R24-'2026년 제부도 통행시간표 (공표자료)'!R92 -> #VALUE! | S24: ='2025년 제부도 통행시간표 (현장자료)'!S24-'2026년 제부도 통행시간표 (공표자료)'!S92 -> #VALUE! | T24: ='2025년 제부도 통행시간표 (현장자료)'!T24-'2026년 제부도 통행시간표 (공표자료)'!T92 -> #VALUE!
A25: 22 | B25: 화 | C25: ='2025년 제부도 통행시간표 (현장자료)'!C25-'2026년 제부도 통행시간표 (공표자료)'!C93 -> #VALUE! | F25: ='2025년 제부도 통행시간표 (현장자료)'!F25-'2026년 제부도 통행시간표 (공표자료)'!F93 -> #VALUE! | H25: 22 | I25: 금 | J25: ='2025년 제부도 통행시간표 (현장자료)'!J25-'2026년 제부도 통행시간표 (공표자료)'!J93 -> #VALUE! | K25: ='2025년 제부도 통행시간표 (현장자료)'!K25-'2026년 제부도 통행시간표 (공표자료)'!K93 -> #VALUE! | L25: ='2025년 제부도 통행시간표 (현장자료)'!L25-'2026년 제부도 통행시간표 (공표자료)'!L93 -> #VALUE! | M25: ='2025년 제부도 통행시간표 (현장자료)'!M25-'2026년 제부도 통행시간표 (공표자료)'!M93 -> #VALUE! | O25: 22 | P25: 월 | Q25: ='2025년 제부도 통행시간표 (현장자료)'!Q25-'2026년 제부도 통행시간표 (공표자료)'!Q93 -> #VALUE! | R25: ='2025년 제부도 통행시간표 (현장자료)'!R25-'2026년 제부도 통행시간표 (공표자료)'!R93 -> #VALUE! | S25: ='2025년 제부도 통행시간표 (현장자료)'!S25-'2026년 제부도 통행시간표 (공표자료)'!S93 -> #VALUE! | T25: ='2025년 제부도 통행시간표 (현장자료)'!T25-'2026년 제부도 통행시간표 (공표자료)'!T93 -> #VALUE!
A26: 23 | B26: 수 | C26: ='2025년 제부도 통행시간표 (현장자료)'!C26-'2026년 제부도 통행시간표 (공표자료)'!C94 -> #VALUE! | F26: ='2025년 제부도 통행시간표 (현장자료)'!F26-'2026년 제부도 통행시간표 (공표자료)'!F94 -> #VALUE! | H26: 23 | I26: 토 | J26: ='2025년 제부도 통행시간표 (현장자료)'!J26-'2026년 제부도 통행시간표 (공표자료)'!J94 -> #VALUE! | K26: ='2025년 제부도 통행시간표 (현장자료)'!K26-'2026년 제부도 통행시간표 (공표자료)'!K94 -> #VALUE! | L26: ='2025년 제부도 통행시간표 (현장자료)'!L26-'2026년 제부도 통행시간표 (공표자료)'!L94 -> #VALUE! | M26: ='2025년 제부도 통행시간표 (현장자료)'!M26-'2026년 제부도 통행시간표 (공표자료)'!M94 -> #VALUE! | O26: 23 | P26: 화 | Q26: ='2025년 제부도 통행시간표 (현장자료)'!Q26-'2026년 제부도 통행시간표 (공표자료)'!Q94 -> #VALUE! | R26: ='2025년 제부도 통행시간표 (현장자료)'!R26-'2026년 제부도 통행시간표 (공표자료)'!R94 -> #VALUE! | S26: ='2025년 제부도 통행시간표 (현장자료)'!S26-'2026년 제부도 통행시간표 (공표자료)'!S94 -> #VALUE! | T26: ='2025년 제부도 통행시간표 (현장자료)'!T26-'2026년 제부도 통행시간표 (공표자료)'!T94 -> -250.81875
A27: 24 | B27: 목 | C27: ='2025년 제부도 통행시간표 (현장자료)'!C27-'2026년 제부도 통행시간표 (공표자료)'!C95 -> #VALUE! | F27: ='2025년 제부도 통행시간표 (현장자료)'!F27-'2026년 제부도 통행시간표 (공표자료)'!F95 -> #VALUE! | H27: 24 | I27: 일 | J27: ='2025년 제부도 통행시간표 (현장자료)'!J27-'2026년 제부도 통행시간표 (공표자료)'!J95 -> #VALUE! | K27: ='2025년 제부도 통행시간표 (현장자료)'!K27-'2026년 제부도 통행시간표 (공표자료)'!K95 -> #VALUE! | L27: ='2025년 제부도 통행시간표 (현장자료)'!L27-'2026년 제부도 통행시간표 (공표자료)'!L95 -> #VALUE! | M27: ='2025년 제부도 통행시간표 (현장자료)'!M27-'2026년 제부도 통행시간표 (공표자료)'!M95 -> #VALUE! | O27: 24 | P27: 수 | Q27: ='2025년 제부도 통행시간표 (현장자료)'!Q27-'2026년 제부도 통행시간표 (공표자료)'!Q95 -> -330.6875 | R27: ='2025년 제부도 통행시간표 (현장자료)'!R27-'2026년 제부도 통행시간표 (공표자료)'!R95 -> #VALUE! | S27: ='2025년 제부도 통행시간표 (현장자료)'!S27-'2026년 제부도 통행시간표 (공표자료)'!S95 -> #VALUE! | T27: ='2025년 제부도 통행시간표 (현장자료)'!T27-'2026년 제부도 통행시간표 (공표자료)'!T95 -> -232.79236
A28: 25 | B28: 금 | C28: ='2025년 제부도 통행시간표 (현장자료)'!C28-'2026년 제부도 통행시간표 (공표자료)'!C96 -> #VALUE! | D28: ='2025년 제부도 통행시간표 (현장자료)'!D28-'2026년 제부도 통행시간표 (공표자료)'!D96 -> #VALUE! | E28: ='2025년 제부도 통행시간표 (현장자료)'!E28-'2026년 제부도 통행시간표 (공표자료)'!E96 -> #VALUE! | F28: ='2025년 제부도 통행시간표 (현장자료)'!F28-'2026년 제부도 통행시간표 (공표자료)'!F96 -> #VALUE! | H28: 25 | I28: 월 | J28: ='2025년 제부도 통행시간표 (현장자료)'!J28-'2026년 제부도 통행시간표 (공표자료)'!J96 -> #VALUE! | K28: ='2025년 제부도 통행시간표 (현장자료)'!K28-'2026년 제부도 통행시간표 (공표자료)'!K96 -> #VALUE! | L28: ='2025년 제부도 통행시간표 (현장자료)'!L28-'2026년 제부도 통행시간표 (공표자료)'!L96 -> #VALUE! | M28: ='2025년 제부도 통행시간표 (현장자료)'!M28-'2026년 제부도 통행시간표 (공표자료)'!M96 -> -243.80556 | O28: 25 | P28: 목 | Q28: ='2025년 제부도 통행시간표 (현장자료)'!Q28-'2026년 제부도 통행시간표 (공표자료)'!Q96 -> -455.68681 | R28: ='2025년 제부도 통행시간표 (현장자료)'!R28-'2026년 제부도 통행시간표 (공표자료)'!R96 -> -1458.2903 | S28: ='2025년 제부도 통행시간표 (현장자료)'!S28-'2026년 제부도 통행시간표 (공표자료)'!S96 -> -1701.1653 | T28: ='2025년 제부도 통행시간표 (현장자료)'!T28-'2026년 제부도 통행시간표 (공표자료)'!T96 -> -249.75903
A29: 26 | B29: 토 | C29: ='2025년 제부도 통행시간표 (현장자료)'!C29-'2026년 제부도 통행시간표 (공표자료)'!C97 -> #VALUE! | D29: ='2025년 제부도 통행시간표 (현장자료)'!D29-'2026년 제부도 통행시간표 (공표자료)'!D97 -> #VALUE! | E29: ='2025년 제부도 통행시간표 (현장자료)'!E29-'2026년 제부도 통행시간표 (공표자료)'!E97 -> #VALUE! | F29: ='2025년 제부도 통행시간표 (현장자료)'!F29-'2026년 제부도 통행시간표 (공표자료)'!F97 -> -303.8125 | H29: 26 | I29: 화 | J29: ='2025년 제부도 통행시간표 (현장자료)'!J29-'2026년 제부도 통행시간표 (공표자료)'!J97 -> -445.66458 | K29: ='2025년 제부도 통행시간표 (현장자료)'!K29-'2026년 제부도 통행시간표 (공표자료)'!K97 -> #VALUE! | L29: ='2025년 제부도 통행시간표 (현장자료)'!L29-'2026년 제부도 통행시간표 (공표자료)'!L97 -> #VALUE! | M29: ='2025년 제부도 통행시간표 (현장자료)'!M29-'2026년 제부도 통행시간표 (공표자료)'!M97 -> -250.77708 | O29: 26 | P29: 금 | Q29: ='2025년 제부도 통행시간표 (현장자료)'!Q29-'2026년 제부도 통행시간표 (공표자료)'!Q97 -> -543.68611 | R29: ='2025년 제부도 통행시간표 (현장자료)'!R29-'2026년 제부도 통행시간표 (공표자료)'!R97 -> -1508.2639 | S29: ='2025년 제부도 통행시간표 (현장자료)'!S29-'2026년 제부도 통행시간표 (공표자료)'!S97 -> -1799.1542
A30: 27 | B30: 일 | C30: ='2025년 제부도 통행시간표 (현장자료)'!C30-'2026년 제부도 통행시간표 (공표자료)'!C98 -> -342.65278 | D30: ='2025년 제부도 통행시간표 (현장자료)'!D30-'2026년 제부도 통행시간표 (공표자료)'!D98 -> #VALUE! | E30: ='2025년 제부도 통행시간표 (현장자료)'!E30-'2026년 제부도 통행시간표 (공표자료)'!E98 -> #VALUE! | F30: ='2025년 제부도 통행시간표 (현장자료)'!F30-'2026년 제부도 통행시간표 (공표자료)'!F98 -> -254.78472 | H30: 27 | I30: 수 | J30: ='2025년 제부도 통행시간표 (현장자료)'!J30-'2026년 제부도 통행시간표 (공표자료)'!J98 -> -544.65903 | K30: ='2025년 제부도 통행시간표 (현장자료)'!K30-'2026년 제부도 통행시간표 (공표자료)'!K98 -> -1540.2639 | L30: ='2025년 제부도 통행시간표 (현장자료)'!L30-'2026년 제부도 통행시간표 (공표자료)'!L98 -> -1712.1486 | M30: ='2025년 제부도 통행시간표 (현장자료)'!M30-'2026년 제부도 통행시간표 (공표자료)'!M98 -> -311.75 | O30: 27 | P30: 토 | R30: ='2025년 제부도 통행시간표 (현장자료)'!R30-'2026년 제부도 통행시간표 (공표자료)'!R98 -> -1530.2368 | S30: ='2025년 제부도 통행시간표 (현장자료)'!S30-'2026년 제부도 통행시간표 (공표자료)'!S98 -> -1846.1451
A31: 28 | B31: 월 | C31: ='2025년 제부도 통행시간표 (현장자료)'!C31-'2026년 제부도 통행시간표 (공표자료)'!C99 -> -515.63333 | D31: ='2025년 제부도 통행시간표 (현장자료)'!D31-'2026년 제부도 통행시간표 (공표자료)'!D99 -> #VALUE! | E31: ='2025년 제부도 통행시간표 (현장자료)'!E31-'2026년 제부도 통행시간표 (공표자료)'!E99 -> #VALUE! | F31: ='2025년 제부도 통행시간표 (현장자료)'!F31-'2026년 제부도 통행시간표 (공표자료)'!F99 -> -311.75694 | H31: 28 | I31: 목 | J31: ='2025년 제부도 통행시간표 (현장자료)'!J31-'2026년 제부도 통행시간표 (공표자료)'!J99 -> -627.64514 | K31: ='2025년 제부도 통행시간표 (현장자료)'!K31-'2026년 제부도 통행시간표 (공표자료)'!K99 -> -1548.2389 | L31: ='2025년 제부도 통행시간표 (현장자료)'!L31-'2026년 제부도 통행시간표 (공표자료)'!L99 -> -1811.134 | M31: ='2025년 제부도 통행시간표 (현장자료)'!M31-'2026년 제부도 통행시간표 (공표자료)'!M99 -> -337.72083 | O31: 28 | P31: 일
A32: 29 | B32: 화 | C32: ='2025년 제부도 통행시간표 (현장자료)'!C32-'2026년 제부도 통행시간표 (공표자료)'!C100 -> -609.62222 | D32: ='2025년 제부도 통행시간표 (현장자료)'!D32-'2026년 제부도 통행시간표 (공표자료)'!D100 -> #VALUE! | E32: ='2025년 제부도 통행시간표 (현장자료)'!E32-'2026년 제부도 통행시간표 (공표자료)'!E100 -> #VALUE! | F32: ='2025년 제부도 통행시간표 (현장자료)'!F32-'2026년 제부도 통행시간표 (공표자료)'!F100 -> -335.73264 | H32: 29 | I32: 금 | J32: ='2025년 제부도 통행시간표 (현장자료)'!J32-'2026년 제부도 통행시간표 (공표자료)'!J100 -> -703.64861 | K32: ='2025년 제부도 통행시간표 (현장자료)'!K32-'2026년 제부도 통행시간표 (공표자료)'!K100 -> -1608.1972 | L32: ='2025년 제부도 통행시간표 (현장자료)'!L32-'2026년 제부도 통행시간표 (공표자료)'!L100 -> -1857.1417 | O32: 29 | P32: 월
A33: 30 | B33: 수 | C33: ='2025년 제부도 통행시간표 (현장자료)'!C33-'2026년 제부도 통행시간표 (공표자료)'!C101 -> -652.60625 | D33: ='2025년 제부도 통행시간표 (현장자료)'!D33-'2026년 제부도 통행시간표 (공표자료)'!D101 -> -1633.2 | E33: ='2025년 제부도 통행시간표 (현장자료)'!E33-'2026년 제부도 통행시간표 (공표자료)'!E101 -> -1807.1153 | F33: ='2025년 제부도 통행시간표 (현장자료)'!F33-'2026년 제부도 통행시간표 (공표자료)'!F101 -> -402.69306 | H33: 30 | I33: 토 | O33: 30 | P33: 화
A34: 31 | B34: 목 | C34: ='2025년 제부도 통행시간표 (현장자료)'!C34-'2026년 제부도 통행시간표 (공표자료)'!C102 -> -729.60556 | H34: 31 | I34: 일
A35: 2025년 10월 통행가능 시간표 | H35: 2025년 11월 통행가능 시간표 | O35: 2025년 12월 통행가능 시간표
A36: 일자 | C36: 1 차 | E36: 2 차 | H36: 일자 | J36: 1 차 | L36: 2 차 | O36: 일자 | Q36: 1 차 | S36: 2 차
C37: ~부터 (열림) | D37: ~까지 (닫힘) | E37: ~부터 (열림) | F37: ~까지 (닫힘) | J37: ~부터 (열림) | K37: ~까지 (닫힘) | L37: ~부터 (열림) | M37: ~까지 (닫힘) | Q37: ~부터 (열림) | R37: ~까지 (닫힘) | S37: ~부터 (열림) | T37: ~까지 (닫힘)
A38: 1 | B38: 수 | H38: 1 | I38: 토 | O38: 1 | P38: 월
A39: 2 | B39: 목 | H39: 2 | I39: 일 | O39: 2 | P39: 화
A40: 3 | B40: 금 | H40: 3 | I40: 월 | K40: ='2025년 제부도 통행시간표 (현장자료)'!K40-'2026년 제부도 통행시간표 (공표자료)'!K108 -> #VALUE! | L40: ='2025년 제부도 통행시간표 (현장자료)'!L40-'2026년 제부도 통행시간표 (공표자료)'!L108 -> #VALUE! | M40: ='2025년 제부도 통행시간표 (현장자료)'!M40-'2026년 제부도 통행시간표 (공표자료)'!M108 -> #VALUE! | O40: 3 | P40: 수
...
